<?xml version="1.0"?>
<robot name="myfirst">
   
  <link name="base_link">
    <visual>
      <origin rpy="0 0 0" xyz="0 0 0"/>
      <geometry>
        <cylinder length="1" radius="5"/>
      </geometry>
    </visual>
    <visual>
      <origin rpy="0 0 0" xyz="0.25 0 1.5"/>
      <geometry>
        <box size="0.5 1 2"/>
      </geometry>
    </visual>
    <collision>
      <geometry>
        <cylinder length="1" radius="5"/>
	<origin rpy="0 0 0" xyz="0 0 0"/>
      </geometry>
    </collision>
    <inertial>
      <mass value="0.1"/>
      <inertia ixx="0.067" ixy="0.0" ixz="0.0" iyy="0.067" iyz="0.0" izz="0.035"/>
    </inertial>
   
  </link>

  <link name="inter_1">
     <visual>
       <origin rpy="0 0 0" xyz="-0.25 1 0"/>
       <geometry>
	 <box size="0.5 1 2"/>
       </geometry>
       <material name="yellow">
         <color rgba="1 1 0 1"/>
       </material>
     </visual>
     <visual>
	<origin rpy="0 0 0" xyz="-0.250 0 -0.5"/>
	<geometry>
		<box size="0.5 1 1"/>
	</geometry>
     </visual>
     <visual>
	<origin rpy="0 0 0" xyz="0.25 1 0.5"/>
	<geometry>
		<box size = "0.5 1 1"/>
	</geometry>
     </visual>
    <inertial>
      <mass value="0.1"/>
      <inertia ixx="0.067" ixy="0.0" ixz="0.0" iyy="0.067" iyz="0.0" izz="0.035"/>
    </inertial>
  </link>

  <joint name="rev_1" type="revolute">
	<origin xyz="0 0 2.5" rpy="0 0 0 "/>
	<parent link= "base_link"/>
	<child link = "inter_1"/>
	<axis xyz="1 0 0"/>
	<limit effort="30" velocity="1.0" lower="-0.45" upper="0.45" />
  </joint>

 <link name="link_2">
    <visual>
      <origin rpy="0 0 0" xyz="0 0 1.5"/>
      <geometry>
        <cylinder length="1" radius="5"/>
      </geometry>
    </visual>
    <visual>
      <origin rpy="0 0 0" xyz="0 0 0.5"/>
      <geometry>
        <box size="0.5 1 1.5"/>
      </geometry>
    </visual>
    <collision>
      <geometry>
        <cylinder length="1" radius="5"/>
	<origin rpy="0 0 0" xyz="0 0 1.5"/>
      </geometry>
    </collision>
    <inertial>
      <mass value="0.5"/>
      <inertia ixx="3.16" ixy="0.0" ixz="0.0" iyy="3.16" iyz="0.0" izz="6.25"/>
    </inertial>
  </link>
  <joint name="rev_2" type="revolute">
	<origin xyz="0 0 0.5" rpy="0 0 0 "/>
	<parent link= "inter_1"/>
	<child link = "link_2"/>
	<axis xyz="0 1 0"/>
	<limit effort="30" velocity="1.0" lower="-0.45" upper="0.45" />
  </joint>

  <link name="link_3">
    
    <visual>
      <origin rpy="0 0 0" xyz="0.25 0 1"/>
      <geometry>
        <box size="0.5 1 2"/>
      </geometry>
    </visual>
    <inertial>
      <mass value="0.1"/>
      <inertia ixx="0.01" ixy="0.0" ixz="0.0" iyy="0.042" iyz="0.0" izz="0.035"/>
    </inertial>
  </link>

  <joint name="fix_1" type="fixed">
	<origin xyz="0 0 2" rpy="0 0 0 "/>
	<parent link= "link_2"/>
	<child link = "link_3"/>
	
  </joint>

  <link name="inter_2">
     <visual>
       <origin rpy="0 0 0" xyz="-0.25 1 0.5"/>
       <geometry>
	 <box size="0.5 1 2"/>
       </geometry>
       <material name="yellow">
         <color rgba="1 1 0 1"/>
       </material>
     </visual>
     <visual>
	<origin rpy="0 0 0" xyz="-0.250 0 0"/>
	<geometry>
		<box size="0.5 1 1"/>
	</geometry>
     </visual>
     <visual>
	<origin rpy="0 0 0" xyz="0.25 1 1"/>
	<geometry>
		<box size = "0.5 1 1"/>
	</geometry>
     </visual>
    <inertial>
      <mass value="0.25"/>
      <inertia ixx="0.4" ixy="0.0" ixz="0.0" iyy="0.4" iyz="0.0" izz="0.2"/>
    </inertial>
  </link>

  <joint name="rev_3" type="revolute">
	<origin xyz="0 0 1.5" rpy="0 0 0 "/>
	<parent link= "link_3"/>
	<child link = "inter_2"/>
	<axis xyz="1 0 0"/>
	<limit effort="30" velocity="1.0" lower="-0.45" upper="0.45" />
  </joint>

 <link name="link_4">
    <visual>
      <origin rpy="0 0 0" xyz="0 0 1.5"/>
      <geometry>
        <cylinder length="1" radius="5"/>
      </geometry>
    </visual>
    <visual>
      <origin rpy="0 0 0" xyz="0 0 0.5"/>
      <geometry>
        <box size="0.5 1 1.5"/>
      </geometry>
    </visual>
    <collision>
      <geometry>
        <cylinder length="1" radius="5"/>
	<origin rpy="0 0 0" xyz="0 0 1.5"/>
      </geometry>
    </collision>
    <inertial>
      <mass value="0.1"/>
      <inertia ixx="0.067" ixy="0.0" ixz="0.0" iyy="0.067" iyz="0.0" izz="0.035"/>
    </inertial>
  </link>

  <link name="camera_link">
    
    <visual>
      <origin rpy="0 0 0" xyz="0 0 0.25"/>
      <geometry>
        <box size="0.5 0.5 0.5"/>
      </geometry>
       <material name="yellow">
         <color rgba="1 1 0 1"/>
       </material>
    </visual>
    <inertial>
      <mass value="0.1"/>
      <inertia ixx="0.01" ixy="0.0" ixz="0.0" iyy="0.042" iyz="0.0" izz="0.035"/>
    </inertial>
  </link>

  <joint name="fix_3" type="fixed">
	<origin xyz="5.25 0 1.25" rpy="0 0 0 "/>
	<parent link= "link_4"/>
	<child link = "camera_link"/>
  </joint>
	

  <joint name="rev_4" type="revolute">
	<origin xyz="0 0 1" rpy="0 0 0 "/>
	<parent link= "inter_2"/>
	<child link = "link_4"/>
	<axis xyz="0 1 0"/>
	<limit effort="30" velocity="1.0" lower="-0.45" upper="0.45" />
  </joint>

  <gazebo>
    <plugin name="gazebo_ros_control" filename="libgazebo_ros_control.so">
      <robotNamespace>/rrbot</robotNamespace>
    </plugin>
  </gazebo> 


   <gazebo reference="camera_link">
    <sensor type="camera" name="camera1">
      <update_rate>30.0</update_rate>
      <camera name="head">
        <horizontal_fov>1.3962634</horizontal_fov>
        <image>
          <width>600</width>
          <height>600</height>
          <format>R8G8B8</format>
        </image>
        <clip>
          <near>0.02</near>
          <far>300</far>
        </clip>
        <noise>
          <type>gaussian</type>
          <!-- Noise is sampled independently per pixel on each frame.
               That pixel's noise value is added to each of its color
               channels, which at that point lie in the range [0,1]. -->
          <mean>0.0</mean>
          <stddev>0.007</stddev>
        </noise>
      </camera>
      <plugin name="camera_controller" filename="libgazebo_ros_camera.so">
        <alwaysOn>true</alwaysOn>
        <updateRate>0.0</updateRate>
        <cameraName>robot/camera1</cameraName>
        <imageTopicName>image_raw</imageTopicName>
        <cameraInfoTopicName>camera_info</cameraInfoTopicName>
        <frameName>camera_link</frameName>
        <hackBaseline>0.07</hackBaseline>
        <distortionK1>0.0</distortionK1>
        <distortionK2>0.0</distortionK2>
        <distortionK3>0.0</distortionK3>
        <distortionT1>0.0</distortionT1>
        <distortionT2>0.0</distortionT2>
      </plugin>
    </sensor>
  </gazebo>

  <transmission name="base_swing_1">
    <type>transmission_interface/SimpleTransmission</type>
    <actuator name="act1_1">
      <mechanicalReduction>1</mechanicalReduction>
    </actuator>
    <joint name="rev_1">
      <hardwareInterface>EffortJointInterface</hardwareInterface>
    </joint>
  </transmission>

  <transmission name="base_swing_2">
    <type>transmission_interface/SimpleTransmission</type>
    <actuator name="act1_2">
      <mechanicalReduction>1</mechanicalReduction>
    </actuator>
    <joint name="rev_2">
      <hardwareInterface>EffortJointInterface</hardwareInterface>
    </joint>
  </transmission>

  <transmission name="firstsw_1">
    <type>transmission_interface/SimpleTransmission</type>
    <actuator name="act2_1">
      <mechanicalReduction>1</mechanicalReduction>
    </actuator>
    <joint name="rev_3">
      <hardwareInterface>EffortJointInterface</hardwareInterface>
    </joint>
  </transmission>

  <transmission name="firstsw_2">
    <type>transmission_interface/SimpleTransmission</type>
    <actuator name="act2_2">
      <mechanicalReduction>1</mechanicalReduction>
    </actuator>
    <joint name="rev_4">
      <hardwareInterface>EffortJointInterface</hardwareInterface>
    </joint>
  </transmission>


</robot>





